Workbook

Sheet HOME
V28: 46163

Sheet 합금1
B2: Alloy1 Machine List
B3: NO | C3: Name | D3: Model | E3: No. | F3: Year | G3: Serial No. | H3: Gal Item No. | I3: No.2 | J3: WCN | K3: PPC | L3: Main Supply | M3: Remark1 | N3: PLC | O3: Model | P3: HMI | Q3: Model | R3: Automation | S3: Robot | T3: Model | U3: Controller | V3: Remark2
B4: 1 | C4: Dorst Mechanical Press | D4: 6t | E4: 12 | F4: 1991 | G4: 109895/1 | H4: 9001590 | I4: 5 | N4: Bachmann | O4: IPM1400 | P4: Bachmann | R4: - | S4: -
B5: 2 | C5: Dorst Hydraulic Press | D5: TPA15HS | E5: =HYPERLINK("#H2!A1","02") -> 02 | F5: 2004 | G5: 300072 | H5: 9002763 | I5: 2 | N5: Bachmann | O5: IPM1400 | P5: Bachmann | R5: Shafir | S5: Fanuc | T5: A-520iA | U5: R-J3
B6: 3 | E6: =HYPERLINK("#H3!A1","03") -> 03 | F6: 2005 | G6: 300227 | H6: 9002763 | I6: 3 | N6: Bachmann | O6: IPM1400 | P6: Bachmann | R6: Shafir | S6: Fanuc | T6: A-520iA | U6: R-J3
B7: 4 | E7: =HYPERLINK("#H5!A1","05") -> 05 | F7: 2005 | G7: 300481 | H7: 9002763 | I7: 5 | N7: Bachmann | O7: IPM1400 | P7: Bachmann | R7: Shafir | S7: Fanuc | T7: A-520iA | U7: R-J3 | AA7: Press | AI7: Sinter | AM7: Sand
B8: 5 | E8: =HYPERLINK("#H6!A1","06") -> 06 | F8: 2005 | G8: 300482 | H8: 9002763 | I8: 6 | N8: Bachmann | O8: IPM1400 | P8: Bachmann | R8: Shafir | S8: Fanuc | T8: A-520iA | U8: R-J3 | AC8: Iscar 32t | AI8: TiN Spread | AJ8: Auto Brush | AM8: Nicolis #10 | AN8: Nicolis #9
B9: 6 | E9: =HYPERLINK("#H7!A1","07") -> 07 | F9: 2005 | G9: 300483 | H9: 9002763 | I9: 7 | N9: Bachmann | O9: IPM1400 | P9: Bachmann | R9: Shafir | S9: Fanuc | T9: A-520iA | U9: R-J3 | AC9: Iscar 12t | AI9: TiN Spread | AK9: HIP#3 | AM9: ISCAR S/B #8 | AN9: ISCAR S/B #1
B10: 7 | E10: =HYPERLINK("#H8!A1","08") -> 08 | F10: 2005 | G10: 300485 | H10: 9002763 | I10: 8 | N10: Bachmann | O10: IPM1400 | P10: Bachmann | R10: Shafir | S10: Fanuc | T10: A-520iA | U10: R-J2 | AI10: Loading | AK10: BATCH#3 | AM10: ISCAR S/B #7 | AN10: ISCAR S/B #2
B11: 8 | E11: 10 | F11: 2005 | G11: 300229 | H11: 9002763 | I11: 10 | N11: Bachmann | O11: IPM1400 | P11: Bachmann | R11: Shafir | S11: Fanuc | T11: A-520iA | U11: R-J3 | AB11: 35T | AC11: OW HM320 | AI11: Loading | AM11: ISCAR S/B #6 | AN11: ISCAR S/B #4
B12: 9 | E12: 11 | F12: 2005 | G12: 300230 | H12: 9002763 | I12: 11 | N12: Bachmann | O12: IPM1400 | P12: Bachmann | R12: Shafir | S12: Fanuc | T12: A-520iA | U12: R-J3 | AB12: ALPHA | AC12: OW SC640 | AK12: HIP#2 | AM12: ISCAR S/B #3 | AN12: Nicolis #11
B13: 10 | E13: 12 | F13: 2005 | G13: 300231 | H13: 9002763 | I13: 12 | N13: Bachmann | O13: IPM1400 | P13: Bachmann | R13: Shafir | S13: Fanuc | T13: A-520iA | U13: R-J3 | AK13: HIP#1 | AM13: ISCAR S/B #5
B14: 11 | E14: 13 | F14: 2010 | G14: 301964 | H14: 9002763 | I14: 14 | N14: Bachmann | O14: IPM1400 | P14: Bachmann | R14: Shafir | S14: Fanuc | T14: A-520iA | U14: R-J3 | AC14: 6T#12 | AG14: HYD#12 | AK14: BATCH#2
B15: 12 | E15: 14 | F15: 2010 | G15: 301965 | H15: 9002763 | I15: 15 | N15: Bachmann | O15: IPM1400 | P15: Bachmann | R15: Shafir | S15: Fanuc | T15: A-520iA | U15: R-J3 | AA15: EP#5 | AC15: HYD#17 | AE15: HYD#10 | AG15: HYD#11 | AJ15: Auto loading | AK15: BATCH#1
B16: 13 | E16: 15 | F16: 2010 | G16: 301966 | H16: 9002763 | I16: 16 | N16: Bachmann | O16: IPM1400 | P16: Bachmann | R16: Shafir | S16: Fanuc | T16: A-520iA | U16: R-J3 | AA16: EP#4 | AC16: HYD#16 | AE16: HYD#8 | AG16: HYD#2
B17: 14 | E17: 16 | F17: 2010 | G17: 301967 | H17: 9002763 | I17: 17 | N17: Bachmann | O17: IPM1400 | P17: Bachmann | R17: Shafir | S17: Fanuc | T17: A-520iA | U17: R-J3 | AA17: EP#3 | AC17: HYD#15 | AE17: HYD#7 | AG17: HYD#3
B18: 15 | E18: 17 | F18: 2010 | G18: 301968 | H18: 9002763 | I18: 18 | N18: Bachmann | O18: IPM1400 | P18: Bachmann | R18: Shafir | S18: Fanuc | T18: A-520iA | U18: R-J3 | AA18: EP#2 | AC18: HYD#14 | AE18: HYD#6 | AG18: OW SP160 #2
B19: 16 | C19: Dorst Electical Press | D19: EP15 | E19: 1 | F19: 2013 | G19: 302835 | H19: 9006020 | I19: 1 | N19: Bachmann | O19: IPM1400 | P19: Bachmann | Q19: DF915DKT | R19: Shafir | S19: Fanuc | T19: LR Mate 200iC | U19: R-30iA | AA19: EP#1 | AC19: HYD#13 | AE19: HYD#5 | AG19: OW SP160 #1
B20: 17 | E20: 2 | F20: 2012 | G20: 302526 | H20: 9006020 | I20: 2 | N20: Bachmann | O20: IPM1400 | P20: Bachmann | Q20: DF915DKT | R20: Shafir | S20: Fanuc | T20: LR Mate 200iC | U20: R-30iA
B21: 18 | E21: 3 | F21: 2012 | G21: 302529 | H21: 9006020 | I21: 3 | N21: Bachmann | O21: IPM1400 | P21: Bachmann | Q21: DF915DKT | R21: Shafir | S21: Fanuc | T21: LR Mate 200iC | U21: R-30iA
B22: 19 | E22: 4 | F22: 2012 | G22: 302527 | H22: 9006020 | I22: 4 | N22: Bachmann | O22: IPM1400 | P22: Bachmann | Q22: DF915DKT | R22: Shafir | S22: Fanuc | T22: LR Mate 200iC | U22: R-30iA
B23: 20 | E23: 5 | F23: 2012 | G23: 302528 | H23: 9006020 | I23: 5 | N23: Bachmann | O23: IPM1400 | P23: Bachmann | Q23: DF915DKT | R23: Shafir | S23: Fanuc | T23: LR Mate 200iC | U23: R-30iA
B24: 21 | C24: Osterwalder Press | D24: SP160 | E24: 1 | F24: 2024 | G24: MN6056 | H24: 9006113 | I24: 11 | R24: Shafir | S24: Fanuc | T24: LR Mate 200iD 7L
B25: 22 | D25: SP160 | E25: 2 | F25: 2024 | G25: MN6057 | H25: 9006113 | I25: 12 | R25: Shafir | S25: Fanuc | T25: LR Mate 200iD 7L
B26: 23 | D26: HM320 | E26: 1 | F26: 2024 | G26: MN6156 | H26: 9008196 | I26: 1 | R26: Raon | S26: Fanuc | V26: 2024.12월 설치 예정
B27: 24 | D27: SC640 | E27: 1 | F27: 2024 | G27: MN6121 | H27: 9008195 | I27: 1 | R27: Osterwalder | S27: Cartesian
B28: 25 | C28: ISCAR 12t Press | D28: 12 ton | E28: 1 | F28: 2012 | G28: - | H28: 9007079 | I28: 1 | N28: PC | O28: - | P28: PC | Q28: - | R28: Iscar | S28: Fanuc | T28: A-520iA | U28: R-J3
B29: 26 | C29: ISCAR EP 32t Press | D29: 32 ton | E29: 1 | F29: 2017 | G29: - | H29: 9000551 | I29: 1 | N29: Beckhoff | O29: C6920-0040 | P29: Beckhoff | Q29: CP6822-0111 | R29: Iscar | S29: Fanuc +Toshiba | T29: LR Mate 200iD +TH850A | U29: Fanuc R-30iB +TS-3100
B30: 27 | C30: Mech. 35t Press | D30: 35 ton | E30: 1 | F30: 1977 | G30: 80882 | H30: 9003378 | I30: 1
B31: 28 | C31: Alpha Press | D31: 40 ton | E31: 1 | F31: 1977 | G31: 40299 | H31: 6185575 | I31: 1
B32: 29 | C32: Cont. F'ce | D32: CHRVF-150T | E32: 1 | F32: 1990 | G32: D-130-688 | H32: 9003390 | I32: 1 | L32: 440v
B33: 30 | D33: CHRVF-150T | E33: 2 | F33: 1994 | G33: D-293-858 | H33: 9003390 | I33: 2
B34: 31 | D34: IVGC-3C-500PT | E34: 3 | F34: 2005 | G34: F-303-317 | H34: 9003691 | I34: 1
B35: 32 | C35: PVA Sinter HIP | D35: COD733RL | E35: 1 | F35: 2020 | G35: COD0100111 | H35: 9002489 | I35: 9 | L35: 380v | N35: Siemens | O35: S7-1500 | P35: Siemens | Q35: -
B36: 33 | E36: 2 | F36: 2008 | G36: PWC010414 | H36: 9002489 | I36: 2 | O36: S7-400 | P36: Intouch | Q36: -
B37: 34 | E37: 3 | F37: 2011 | G37: COD0100012 | H37: 9002489 | I37: 6 | O37: S7-400 | P37: Intouch | Q37: -
B38: 35 | C38: Iscar Sand Deburring | D38: Old | E38: 1 | F38: 1999 | G38: 1 | H38: 9004004 | I38: 2 | L38: 220v | R38: Iscar | S38: Manz | T38: Staubli | U38: SR8 plus
B39: 36 | E39: 2 | F39: 2000 | G39: 2 | H39: 9004004 | I39: 3
B40: 37 | D40: Modify M/C (Neo Blast) | E40: 3 | F40: 2000 | G40: 3 | H40: 9004004 | I40: 4
B41: 38 | E41: 4 | F41: 1999 | G41: 4 | H41: 9004004 | I41: 5
...

Sheet 합금2
B2: Alloy2 Machine List
B3: NO | C3: Name | D3: Model | E3: No. | F3: Year | G3: Serial No. | H3: Gal Item No. | I3: No.2 | J3: WCN | K3: PPC | L3: Main Supply | M3: Remark1 | N3: PLC | O3: Model | P3: HMI | Q3: Model | R3: Automation | S3: Robot | T3: Model | U3: Controller | V3: Remark2
B4: 1 | C4: Kobayashi Press | D4: DX2-10ADT | E4: 1 | F4: 2011 | G4: MC1101-06 | H4: 9005709 | I4: 1 | L4: 220V | R4: Shafir | S4: Toshiba | T4: TH850A
B5: 2 | E5: 2 | F5: 2011 | G5: MC1101-07 | H5: 9005709 | I5: 2 | L5: 220V | R5: Shafir | S5: Toshiba | T5: TH850A
B6: 3 | E6: 3 | F6: 2011 | G6: MC1101-10 | H6: 9005709 | I6: 3 | L6: 220V | R6: Shafir | S6: Toshiba | T6: TH850A
B7: 4 | E7: 4 | F7: 2011 | G7: MC1101-04 | H7: 9005709 | I7: 4 | L7: 220V | R7: Shafir | S7: Toshiba | T7: TH850A | AA7: 합금2
B8: 5 | E8: 5 | F8: 2011 | G8: MC1101-09 | H8: 9005709 | I8: 5 | L8: 220V | R8: Shafir | S8: Toshiba | T8: TH850A | AA8: Koba #1 | AB8: Koba #2 | AC8: Koba #3 | AD8: Koba #4 | AE8: Koba #5
B9: 6 | E9: 6 | F9: 2011 | G9: MC1101-03 | H9: 9005709 | I9: 6 | L9: 220V | R9: Shafir | S9: Toshiba | T9: TH850A | AA9: Koba #6 | AB9: Koba #7 | AC9: Koba #8 | AD9: Koba #9 | AE9: Koba #10 | AH9: SinterHIP#1 | AJ9: SinterHIP#2
B10: 7 | E10: 7 | F10: 2011 | G10: MC1101-05 | H10: 9005709 | I10: 7 | L10: 220V | R10: Shafir | S10: Toshiba | T10: TH850A | AA10: Koba #11 | AB10: Koba #12 | AC10: Koba #13 | AD10: Koba #14 | AE10: Koba #15
B11: 8 | E11: 8 | F11: 2011 | G11: MC1101-01 | H11: 9005709 | I11: 8 | L11: 220V | R11: Shafir | S11: Toshiba | T11: TH850A | AG11: Loading #1 | AH11: Loading #2 (Iscar New) | AI11: Loading #3
B12: 9 | E12: 9 | F12: 2011 | G12: MC1101-02 | H12: 9005709 | I12: 9 | L12: 220V | R12: Shafir | S12: Toshiba | T12: TH850A | AB12: OW #10 | AC12: OW #7 | AD12: OW #4 | AE12: OW #1 | AJ12: SinterHIP#3
B13: 10 | E13: 10 | F13: 2011 | G13: MC1101-08 | H13: 9005709 | I13: 10 | L13: 220V | R13: Shafir | S13: Toshiba | T13: TH850A | AC13: OW #8 | AD13: OW #5 | AE13: OW #2 | AI13: HC/RMS
B14: 11 | E14: 11 | F14: 2012 | G14: MC1101-13 | H14: 9005709 | I14: 11 | L14: 220V | R14: Shafir | S14: Toshiba | T14: TH850A | AC14: OW #9 | AD14: OW #6 | AE14: OW #3 | AI14: Feed Cleaner | AJ14: TiN Spread
B15: 12 | E15: 12 | F15: 2012 | G15: MC1101-11 | H15: 9005709 | I15: 12 | L15: 220V | R15: Shafir | S15: Toshiba | T15: TH850A
B16: 13 | E16: 13 | F16: 2012 | G16: MC1101-15 | H16: 9005709 | I16: 13 | L16: 220V | R16: Shafir | S16: Toshiba | T16: TH850A
B17: 14 | E17: 14 | F17: 2012 | G17: MC1101-12 | H17: 9005709 | I17: 14 | L17: 220V | R17: Shafir | S17: Toshiba | T17: TH850A
B18: 15 | E18: 15 | F18: 2012 | G18: MC1101-14 | H18: 9005709 | I18: 15 | L18: 220V | R18: Shafir | S18: Toshiba | T18: TH850A
B19: 16 | C19: Osterwalder Press | D19: SP160 | E19: 1 | F19: 2021 | G19: MN5880 | H19: 9006113 | I19: 1 | R19: Shafir | S19: Fanuc | T19: LR Mate 200iD 7L
B20: 17 | E20: 2 | F20: 2021 | G20: MN5885 | H20: 9006113 | I20: 2 | R20: Shafir | S20: Fanuc | T20: LR Mate 200iD 7L
B21: 18 | E21: 3 | F21: 2021 | G21: MN5920 | H21: 9006113 | I21: 3 | R21: Shafir | S21: Fanuc | T21: LR Mate 200iD 7L
B22: 19 | E22: 4 | F22: 2021 | G22: MN5882 | H22: 9006113 | I22: 4 | R22: Shafir | S22: Fanuc | T22: LR Mate 200iD 7L
B23: 20 | E23: 5 | F23: 2021 | G23: MN5918 | H23: 9006113 | I23: 5 | R23: Shafir | S23: Fanuc | T23: LR Mate 200iD 7L
B24: 21 | E24: 6 | F24: 2021 | G24: MN5921 | H24: 9006113 | I24: 6 | R24: Shafir | S24: Fanuc | T24: LR Mate 200iD 7L | V24: Pallet Issue
B25: 22 | E25: 7 | F25: 2021 | G25: MN5884 | H25: 9006113 | I25: 7 | R25: Shafir | S25: Fanuc | T25: LR Mate 200iD 7L
B26: 23 | E26: 8 | F26: 2021 | G26: MN5919 | H26: 9006113 | I26: 8 | R26: Shafir | S26: Fanuc | T26: LR Mate 200iD 7L
B27: 24 | E27: 9 | F27: 2021 | G27: MN5922 | H27: 9006113 | I27: 9 | R27: Shafir | S27: Fanuc | T27: LR Mate 200iD 7L
B28: 25 | E28: 10 | F28: 2021 | G28: MN5879 | H28: 9006113 | I28: 10 | R28: Shafir | S28: Fanuc | T28: LR Mate 200iD 7L
B29: 26 | C29: PVA Sinter HIP | D29: COD733RL | E29: 1 | F29: 2011 | G29: COD0100030 | H29: 9002489 | I29: 4
B30: 27 | E30: 2 | F30: 2012 | G30: COD0100031 | H30: 9002489 | I30: 3
B31: 28 | E31: 3 | F31: 2012 | G31: COD0100040 | H31: 9002489 | I31: 5
B32: 29 | C32: Auto Loading | D32: ISCAR (Manz) | E32: 1 | F32: 2009 | G32: 9005464-02 | H32: 9001904 | I32: 2 | R32: Iscar | S32: Manz | T32: Staubli
B33: 30 | D33: Old | E33: 2 | F33: 2009 | G33: 9005464-01 | H33: 9001904 | I33: 3 | L33: 2024 폐기
B34: 30 | D34: ISCAR (Fanuc) | E34: 2 | F34: 2021 | G34: 9007743-02 | H34: 9010004 | I34: 3 | R34: Iscar | S34: Fanuc
B35: 31 | D35: 성림비전 | E35: 3 | F35: 2024 | G35: SUMT-24-01 | I35: 1 | R35: 성림비전 | S35: Cartesian | T35: -
B36: 32 | C36: Feeder Cleaner | D36: Auto Cleaner | E36: 1 | F36: 2013 | G36: - | H36: 6188538 | I36: 1
B37: 33 | C37: TiN Spread | D37: Tray Packing | E37: 1 | F37: 2011 | G37: 10100040 | H37: 9005794 | I37: 1
B38: 34 | D38: Tray Packing | E38: 2 | F38: 2024 | M38: 24/11/27 입고. 하이테크
H83: 9003763
U97: #13~#17

Sheet 금형1
B2: Die1 Machine List
B3: NO | C3: Name | D3: Model | E3: No. | F3: Year | G3: Serial No. | H3: Gal Item No. | I3: No.2 | J3: WCN | K3: PPC | L3: Main Supply | M3: Remark1 | N3: PLC | O3: Model | P3: HMI | Q3: Model | R3: Fire Ext.
B4: 1 | C4: Makino Milling | D4: V22 | E4: 1 | F4: 2005 | G4: 236 | H4: 9005275 | I4: 1 | L4: 220V | Q4: 310is-A5
B5: 2 | E5: 2 | F5: 2006 | G5: 364 | H5: 9005275 | I5: 2 | L5: 220V
B6: 3 | E6: 3 | F6: 2006 | G6: 363 | H6: 9005275 | I6: 3 | L6: 220V
B7: 4 | E7: 4 | F7: 2008 | G7: 484 | H7: 9003789 | I7: 1 | L7: 220V
B8: 5 | E8: 5 | F8: 2010 | G8: 569 | H8: 9005275 | I8: 4 | L8: 220V | Q8: 31is-A5
B9: 6 | D9: MS30 | E9: 1 | F9: 1998 | G9: A93-041 | H9: 6198321 | I9: 1 | L9: 220V
B10: 7 | C10: Roders Milling | D10: RXP501DSC | E10: 1 | F10: 2024 | G10: 16385-211 | H10: 9008088 | I10: 1 | L10: 220V | AA10: 금형1
B11: 8 | C11: GF EDM | D11: EDM350 | E11: 1 | F11: 2006 | G11: 642543 | H11: 9003822 | I11: 1 | L11: 380V | Q11: 180i-MB | AA11: Brazing M/C | AD11: Aero Lap#1 | AF11: Band Saw
B12: 9 | E12: 2 | F12: 2006 | G12: 642542 | H12: 9003822 | I12: 2 | L12: 380V | AA12: Profile PGX #1 | AC12: Profile G/R#1 | AD12: Surface G/R#1 | AE12: Tool G/R#1 | AF12: 화천 #1
B13: 10 | E13: 3 | F13: 2005 | G13: 642237 | H13: 9003822 | I13: 3 | L13: 380V
B14: 11 | E14: 4 | F14: 2005 | G14: 642408 | H14: 9003822 | I14: 4 | L14: 380V | AA14: Rotating L/P#1 | AB14: Brazing M/C#1 | AD14: Amada | AF14: MS30#1
B15: 12 | E15: 5 | F15: 2011 | G15: 281 | H15: 9005778 | I15: 1 | L15: 380V | AA15: Extrude Hone#1 | AF15: V22#5
B16: 13 | D16: EDM35P | E16: 1 | F16: 2004 | G16: 641549 | H16: 9003504 | I16: 1 | L16: 380V | AD16: EDM#4 | AF16: V22#4
B17: 14 | C17: GF Wire cutting | D17: 240CC | E17: 3 | F17: 2006 | G17: 921494 | H17: 9003995 | I17: 1 | L17: 380V | Q17: 180i-w | AD17: EDM#3 | AF17: V22#3
B18: 15 | E18: 4 | F18: 2008 | G18: 921812 | H18: 9003995 | I18: 2 | L18: 380V | AA18: Wire #2 | AB18: 240CC#1 | AD18: EDM#2 | AF18: V22#2
B19: 16 | C19: Brazing machine | D19: KHF-30 | E19: 1 | F19: 1998 | H19: 9006171 | I19: 3 | L19: 220V | AA19: Wire #1 | AB19: 240CC#2 | AD19: EDM#1 | AF19: V22#1
B20: 17 | C20: 화천선반 | D20: WHPL380X750 | E20: 1 | F20: 2000 | G20: 213039 | H20: 6193045 | I20: 1 | L20: 220V | AD20: EDM35P#1 | AF20: Roders
B21: 18 | C21: Tool Grinder | D21: C-40 | E21: 1 | F21: 1998 | G21: 100974 | H21: 9005524 | I21: 1 | L21: 220V | AD21: EDM#5 (SP)
B22: 19 | C22: 평면연삭기 | D22: YGS 50A | E22: 1 | F22: 2006 | G22: 5060721 | H22: 9003403 | I22: 1 | L22: 220V
B23: 20 | C23: Profile | D23: PGX-2000S | E23: 1 | F23: 1988 | G23: 704 | H23: 6183510 | I23: 1 | L23: 220V
B24: 21 | C24: AMAGA Profile | D24: DPG-150 | E24: 1 | F24: 2024 | G24: 1150067 | H24: 9008237 | I24: 1
B25: 22 | C25: Aero lap | D25: YT-300 | E25: 1 | F25: 2003 | G25: - | H25: 9005509 | I25: 1 | L25: 1P 110V
B26: 23 | C26: Extrude hone | D26: 77c | E26: 1 | F26: 1998 | G26: - | H26: - | I26: - | L26: 380V | V26: 2023
B27: 24 | C27: Band saw | D27: HVS50 | E27: 1 | F27: 1995 | G27: - | H27: 6320179 | I27: 1 | L27: 220V
B28: 25 | C28: Rotating L/P | D28: 돌돌이 | E28: 1 | F28: 2002 | G28: - | H28: - | I28: - | L28: 220V
H82: 9003763
M96: #13~#17

Sheet 금형2
B2: Die2 Machine List
B3: NO | C3: Name | D3: Model | E3: No. | F3: Year | G3: Serial No. | H3: Gal Item No. | I3: No.2 | J3: WCN | K3: PPC | L3: Main Supply | M3: Remark1 | N3: PLC | O3: Model | P3: HMI | Q3: Model | R3: Fire Ext. | AA3: 금형2
B4: 1 | C4: Makino Milling | D4: V22 | E4: 1 | F4: 2012 | G4: 606 | H4: 9005275 | I4: 5 | AA4: Blast | AB4: Wire#1 | AC4: Makino#1
B5: 2 | E5: 2 | F5: 2012 | G5: 607 | H5: 9005275 | I5: 6 | AA5: Youil | AB5: Wire#2 | AC5: Makino#2
B6: 3 | C6: GF EDM | D6: EDM350 | E6: 1 | F6: 2012 | G6: 0329 | H6: 9006152 | I6: 1 | AA6: Brazing | AB6: EDM#1 | AC6: Roders
B7: 4 | E7: 2 | F7: 2012 | G7: 0330 | H7: 9006152 | I7: 2 | AB7: EDM#2
B8: 5 | C8: GF Wire cutting | D8: 240CC | E8: 1 | F8: 2012 | G8: 0072 | H8: 9006158 | I8: 1
B9: 6 | E9: 2 | F9: 2012 | G9: 0071 | H9: 9006158 | I9: 2
B10: 7 | C10: Roders Milling | D10: RXP501DSC | E10: 1 | F10: 2024 | G10: 16385-211 | H10: 9008088 | I10: 2 | L10: 400V 22kVA
B11: 8 | C11: Brazing Sehyang | D11: Brazing 2541 | E11: 1 | F11: 2012 | G11: SHK030K-220-10 | H11: 9006171 | I11: 2
B12: 9 | C12: Youil Grinding | D12: YGS-50A | E12: 1 | F12: 2012 | G12: 50120104 | H12: 9006002 | I12: 1
B13: 10 | C13: BLASTING MACHINE | D13: YT-300 | E13: 1 | F13: 2012 | G13: 0273 | H13: 9004435 | I13: 1
H83: 9003763
M97: #13~#17

Sheet 연삭1
B2: Grinding1 Machine List
B3: NO | C3: Name | D3: Model | E3: No. | F3: Year | G3: Serial No. | H3: Gal Item No. | I3: No.2 | J3: WCN | K3: PPC | L3: Main Supply | M3: Remark1 | N3: PLC | O3: Model | P3: HMI | Q3: Model | R3: Automation | S3: Robot | T3: Model | U3: Controller | V3: Remark2 | W3: Fire Ext.
B4: 1 | C4: Wendt WAC735 | D4: Scalar | E4: 1 | F4: 2004 | G4: 851190902A | H4: 9003194 | I4: 1 | N4: Bosch | O4: IndraMotion MTX | P4: Rexroth | Q4: BTV16 | R4: Wendt | S4: Adept | T4: Cobra 600 | U4: CIP2 RA4 | W4: K&B
B5: 2 | E5: 2 | F5: 2004 | G5: 851190901A | H5: 9003194 | I5: 2 | W5: K&B
B6: 3 | E6: 3 | F6: 2004 | G6: 851190903A | H6: 9003194 | I6: 3 | Q6: P16 | W6: K&B
B7: 4 | E7: 4 | F7: 2004 | G7: 851190904A | H7: 9003194 | I7: 4 | Q7: BTV16 | W7: K&B
B8: 5 | E8: 5 | F8: 2004 | G8: 851190905A | H8: 9003194 | I8: 5 | W8: K&B
B9: 6 | E9: 6 | F9: 2004 | G9: 851190906A | H9: 9003194 | I9: 6 | T9: Cobra S600 | U9: Smart Controller CX (P/N: 20000-310) 장비 PLC Rexroth = I/O Card 포함 | W9: K&B
B10: 7 | E10: 7 | F10: 2004 | G10: 851191107A | H10: 9003194 | I10: 7 | W10: K&B
B11: 8 | E11: 8 | F11: 2004 | G11: 851191108A | H11: 9003194 | I11: 8 | W11: K&B
B12: 9 | E12: 9 | F12: 2004 | G12: 851191202A | H12: 9003194 | I12: 9 | Q12: P16 | W12: K&B
B13: 10 | E13: 10 | F13: 2004 | G13: 851191201A | H13: 9003194 | I13: 10 | Q13: BTV16 | W13: K&B
B14: 11 | E14: 11 | F14: 2005 | G14: 851191207A | H14: 9003194 | I14: 11 | W14: K&B
B15: 12 | E15: 12 | F15: 2005 | G15: 851191208A | H15: 9003194 | I15: 12 | W15: K&B
B16: 13 | E16: 13 | F16: 2005 | G16: 851151604A | H16: 9003194 | I16: 13 | W16: K&B
B17: 14 | E17: 14 | F17: 2005 | G17: 851151605A | H17: 9003194 | I17: 14 | W17: K&B
B18: 15 | E18: 15 | F18: 2005 | G18: 851151606A | H18: 9003194 | I18: 15 | W18: K&B
B19: 16 | E19: 16 | F19: 2005 | G19: 851151609X | H19: 9003194 | I19: 16 | W19: K&B
B20: 17 | E20: 17 | F20: 2005 | G20: 851151607X | H20: 9003194 | I20: 17 | W20: K&B
B21: 18 | E21: 19 | F21: 2006 | G21: 851152201A | H21: 9003194 | I21: 19 | N21: Rexroth | Q21: VDP16 | W21: K&B
B22: 19 | E22: 20 | F22: 2006 | G22: 851152202A | H22: 9003194 | I22: 20 | W22: K&B
B23: 20 | E23: 21 | F23: 2007 | G23: 851152204A | H23: 9003194 | I23: 21 | W23: K&B
B24: 21 | E24: 22 | F24: 2007 | G24: 851152205A | H24: 9003194 | I24: 22 | W24: K&B
B25: 22 | E25: 23 | F25: 2005 | G25: 851151602A | H25: 9003194 | I25: 23 | N25: Bosch | Q25: BTV16 | W25: K&B
B26: 23 | E26: 24 | F26: 2005 | G26: 851151603A | H26: 9003194 | I26: 24 | W26: K&B
B27: 24 | E27: 29 | F27: 2007 | G27: 851152203T | H27: 9003194 | I27: 31 | N27: Rexroth | Q27: VDP16 | W27: K&B
B28: 25 | D28: Quattro | E28: 25 | F28: 2010 | G28: 851422706A | H28: 9003194 | I28: 29 | W28: K&B
B29: 26 | E29: 27 | F29: 2010 | G29: 851422711T | H29: 9003194 | I29: 28 | W29: K&B
B30: 27 | E30: 28 | F30: 2010 | G30: 851422702A | H30: 9003194 | I30: 30 | W30: K&B
B31: 28 | D31: Centro | E31: 1 | F31: 2006 | G31: 851141907A | H31: 9003277 | I31: 1 | N31: Rexroth | Q31: IndraControlV | T31: Cobra S800 | W31: K&B
B32: 29 | E32: 2 | F32: 2012 | G32: 851143016A | H32: 9003277 | I32: 2 | N32: Bosch | Q32: BTV16 | W32: K&B | AA32: 연삭 Grinding
B33: 30 | E33: 3 | F33: 2016 | G33: 851144303A | H33: 9003277 | I33: 3 | N33: Rexroth | Q33: IndraControlV | W33: K&B | AA33: Laser marking (EL) | AF33: Okano #4 | AG33: Okano #3 | AH33: Okano #2 | AI33: Okano #1
B34: 31 | E34: 4 | F34: 2016 | G34: 851144304A | H34: 9003277 | I34: 4 | W34: K&B | AF34: Zoller
B35: 32 | E35: 5 | F35: 2012 | G35: 851143012X | H35: 9003277 | I35: 5 | W35: K&B | AA35: Zoller (New)
B36: 33 | C36: Wendt WBM | D36: 271RF | E36: 7 | F36: 2006 | G36: 855010403A | H36: 9002212 | I36: 3 | N36: Siemens | O36: 840DI | P36: Siemens | Q36: PCU 50.3-C | T36: Cobra S600 (Dual) | W36: K&B | AA36: Centro#1 | AB36: Centro#2 | AC36: Centro#3 | AD36: Centro#4 | AF36: Quattro#27 | AG36: Quattro#25 | AH36: Combi#17
B37: 34 | E37: 8 | F37: 2010 | G37: 855010601A | H37: 9002212 | I37: 4 | N37: Siemens | O37: 840DI | P37: Siemens | Q37: PCU 50.3-C | W37: K&B
B38: 35 | C38: Waida | D38: APX105 | E38: 1 | F38: 2024 | G38: 264 | H38: 9000428 | I38: 14 | R38: Waida | S38: Yamaha | T38: YK800XGP | U38: RCX320+RCX340 | W38: K&B | AA38: Combi#16 | AB38: Combi#15 | AC38: Combi#14 | AD38: Combi#13 | AF38: Combi#19 | AG38: Combi#20 | AH38: Quattro#28
B39: 36 | E39: 2 | F39: 2024 | G39: 265 | H39: 9000428 | I39: 15 | R39: Waida | S39: Yamaha | T39: YK800XGP | U39: RCX320+RCX340 | W39: K&B | AA39: Combi#12 | AB39: Combi#11 | AC39: Combi#10 | AD39: Combi#9 | AF39: Combi#29 | AG39: Agathon Penta | AH39: Centro #5
A40: ㅑ | B40: 37 | E40: 3 | F40: 2024 | G40: 266 | H40: 9000428 | I40: 16 | R40: Waida | S40: Yamaha | T40: YK800XGP | U40: RCX320+RCX340 | W40: K&B
B41: 38 | E41: 4 | F41: 2024 | G41: 269 | H41: 9000428 | I41: 19 | R41: Waida | S41: Yamaha | T41: YK800XGP | U41: RCX320+RCX340 | W41: K&B | AA41: Combi#8 | AB41: Combi#6 | AC41: Combi#5 | AD41: Combi#4 | AF41: AP460E#6 | AG41: AP460E#5 | AH41: AP30#1
...

Sheet 연삭2
B2: Grinding2 Machine List
B3: NO | C3: Name | D3: Model | E3: No. | F3: Year | G3: Serial No. | H3: Gal Item No. | I3: No.2 | J3: WCN | K3: PPC | L3: Main Supply | M3: Remark1 | N3: PLC | O3: Model | P3: HMI | Q3: Model | R3: Automation | S3: Robot | T3: Model | U3: Controller | V3: Remark2 | W3: Fire Ext.
B4: 1 | C4: Waida | D4: AP710 | E4: 1 | F4: 2012 | G4: 164 | H4: 9005443 | I4: 12 | R4: Waida | S4: IAI | T4: IX-NNW7020 | U4: XSEL-QX5-NNW7020-100A-PR-E-EEE-0-3-SP
B5: 2 | E5: 2 | F5: 2012 | G5: 163 | H5: 9005443 | I5: 13 | R5: Waida
B6: 3 | E6: 3 | F6: 2012 | G6: 162 | H6: 9005443 | I6: 14 | R6: Waida
B7: 4 | E7: 4 | F7: 2013 | G7: 161 | H7: 9005443 | I7: 15 | R7: Waida
B8: 5 | D8: APX103 | E8: 1 | F8: 2013 | G8: 141 | H8: 9006551 | I8: 1 | R8: Waida | S8: Yamaha | T8: YK800XGP | U8: SR1-X
B9: 6 | E9: 2 | F9: 2013 | G9: 142 | H9: 9006551 | I9: 2 | R9: Waida
B10: 7 | E10: 3 | F10: 2013 | G10: 145 | H10: 9006551 | I10: 3 | R10: Waida
B11: 8 | E11: 4 | F11: 2013 | G11: 146 | H11: 9006551 | I11: 4 | R11: Waida
B12: 9 | E12: 5 | F12: 2013 | G12: 147 | H12: 9006551 | I12: 5 | R12: Waida
B13: 10 | E13: 6 | F13: 2015 | G13: 214 | H13: 9006551 | I13: 6 | R13: Waida
B14: 11 | E14: 7 | F14: 2015 | G14: 197 | H14: 9006551 | I14: 7 | R14: Waida
B15: 12 | E15: 8 | F15: 2015 | G15: 198 | H15: 9006551 | I15: 8 | R15: Waida
B16: 13 | E16: 9 | F16: 2015 | G16: 215 | H16: 9006551 | I16: 9 | R16: Waida
B17: 14 | D17: APX105 | E17: 1 | F17: 2018 | G17: 136 | H17: 9000428 | I17: 1 | R17: Waida
B18: 15 | E18: 2 | F18: 2018 | G18: 137 | H18: 9000428 | I18: 2 | R18: Waida
B19: 16 | E19: 3 | F19: 2018 | G19: 170 | H19: 9000428 | I19: 3 | R19: Waida
B20: 17 | E20: 4 | F20: 2019 | G20: 181 | H20: 9000428 | I20: 4 | R20: Waida
B21: 18 | E21: 5 | F21: 2019 | G21: 169 | H21: 9000428 | I21: 7 | R21: Waida
B22: 19 | E22: 6 | F22: 2019 | G22: 182 | H22: 9000428 | I22: 8 | R22: Waida
B23: 20 | E23: 7 | F23: 2019 | G23: 191 | H23: 9000428 | I23: 9 | R23: Waida
B24: 21 | E24: 8 | F24: 2024 | G24: 256 | H24: 9000428 | I24: 12 | R24: Waida
B25: 22 | E25: 9 | F25: 2024 | G25: 257 | H25: 9000428 | I25: 13 | R25: Waida
B26: 23 | D26: APX-F50 | E26: 1 | F26: 2023 | G26: 122 | H26: 9008045 | I26: 1 | R26: Waida | S26: Fanuc | T26: LR Mate 200iD 7L | U26: R-30iB
B27: 24 | E27: 2 | F27: 2024 | G27: 125 | H27: 9008045 | I27: 2 | R27: Waida | S27: Fanuc | T27: LR Mate 200iD 7L | U27: R-30iB
B28: 25 | E28: 3 | F28: 2024 | G28: 146 | H28: 9008045 | I28: 3 | R28: Waida | S28: Fanuc | T28: LR Mate 200iD 7L
B29: 26 | E29: 4 | F29: 2024 | G29: 147 | H29: 9008045 | I29: 4 | R29: Waida | S29: Fanuc | T29: LR Mate 200iD 7L
B30: 27 | E30: 5 | F30: 2024 | G30: 148 | H30: 9008045 | I30: 5 | R30: Waida | S30: Fanuc | T30: LR Mate 200iD 7L
B31: 28 | E31: 6 | F31: 2024 | G31: 149 | H31: 9008045 | I31: 6 | R31: Waida | S31: Fanuc | T31: LR Mate 200iD 7L
B32: 29 | C32: Wendt | D32: 271RF | E32: 5 | F32: 2002 | G32: 855190102X | H32: 9002212 | I32: 1 | R32: Wendt | S32: Adept | T32: Cobra 600 (Dual)
B33: 30 | E33: 6 | F33: 2006 | G33: 855010303A | H33: 9002212 | I33: 2 | R33: Wendt | S33: Adept | T33: Cobra S600 (Dual)
B34: 31 | C34: Stahli | D34: DLM705 | E34: 1 | F34: 2010 | G34: 10 08 1152 | H34: 9003232 | I34: 1 | R34: Shafir | S34: Adept | T34: Cobra S600 (Dual)
B35: 32 | E35: 2 | F35: 2023 | G35: 1604 | H35: 9003232 | I35: 2 | R35: Shafir | S35: Fanuc | T35: SR-6iA (Dual)
B36: 33 | E36: 3 | F36: 2023 | G36: 1605 | H36: 9003232 | I36: 3 | R36: Shafir | S36: Fanuc | T36: SR-6iA (Dual)
B37: 34 | D37: FLM602 | E37: 1 | F37: 2013 | G37: 9006180/03 | H37: 9006089 | I37: 1 | R37: Shafir | S37: Adept | T37: Quattro S650H
B38: 35 | C38: EWAG | D38: Compact Line | E38: 1 | F38: 2019 | G38: 7188-0224 | H38: 9006069 | I38: 1 | R38: EWAG | S38: Fanuc | T38: LR Mate 200iD
B39: 36 | E39: 2 | F39: 2019 | G39: 7188-0225 | H39: 9006069 | I39: 2 | R39: EWAG | S39: Fanuc | T39: LR Mate 200iD
B40: 37 | E40: 3 | F40: 2019 | G40: 7188-0243 | H40: 9006069 | I40: 3 | R40: EWAG | S40: Fanuc | T40: LR Mate 200iD
B41: 38 | E41: 4 | F41: 2024 | G41: 2188-0021 | H41: 9006069 | I41: 4 | R41: EWAG | S41: Fanuc
...

Sheet 코팅1
B2: Coating1 Machine List
B3: NO | C3: Name | D3: Model | E3: No. | F3: Year | G3: Serial No. | H3: Gal Item No. | I3: No.2 | J3: WCN | K3: PPC | L3: Main Supply | M3: Remark1 | N3: PLC | O3: Model | P3: HMI | Q3: Model | R3: Automation | S3: Robot | T3: Model | U3: Controller | V3: Remark2
B4: 1 | C4: PVD F'ce | D4: Balzers BAI830 | E4: 1 | F4: 2000 | G4: BB455 567-S | H4: 9001028 | I4: 1 | L4: 380V 48kVA | N4: Balzers | O4: 자체 I/O | P4: Gercom | Q4: GC-10R-24F
B5: 2 | E5: 2 | F5: 2011 | G5: 94-97355 | H5: 9001028 | I5: 2 | N5: Balzers | O5: 자체 I/O | P5: Gercom | Q5: GC-10R-24F
B6: 3 | D6: Balzers BAI900 | E6: 3 | F6: 2017 | G6: 99-0000504905 | H6: 9001290 | I6: 1 | N6: Matsushita | O6: NAIS FP3 | P6: PC | Q6: -
B7: 4 | D7: Kobe AIP-S70 | E7: 1 | F7: 2001 | G7: EB10131 | H7: 9001962 | I7: 1 | N7: YOKOGAWA | O7: FACTORY ACE | P7: PC | Q7: -
B8: 5 | E8: 2 | F8: 2005 | G8: EB10211 | H8: 9001962 | I8: 2 | N8: YOKOGAWA | O8: FACTORY ACE | P8: PC | Q8: -
B9: 6 | E9: 3 | F9: 2007 | G9: EB10260 | H9: 9001962 | I9: 3 | N9: YOKOGAWA | O9: FACTORY ACE | P9: PC | Q9: -
B10: 7 | E10: 4 | F10: 2011 | G10: EB10377 | H10: 9001962 | I10: 4 | N10: YOKOGAWA | O10: FACTORY ACE | P10: PC | Q10: -
B11: 8 | C11: CVD F'ce | D11: Bernex BPX 530L Tandem | E11: 3 | F11: 1999 | G11: 519616 | H11: 9001889 | I11: 1 | L11: 220V 90kVA | N11: ALLEN BRADLEY | O11: SLC-500 | P11: V1.6.3 | Q11: - | AA11: 코팅1
B12: 9 | E12: 4 | F12: 2014 | G12: 19528/526117 | H12: 9001104 | I12: 2 | P12: V2.0.21 | Q12: - | AD12: Bernex #9 | AE12: Bernex #8 | AF12: Bernex #7 | AH12: Dry Sand New | AI12: Balzers #1
B13: 10 | E13: 5 | F13: 2014 | G13: 19530/526120 | H13: 9001104 | I13: 3 | P13: V2.0.21 | Q13: - | AB13: Macoho #5 | AC13: Bernex #6 | AD13: Bernex #5 | AE13: Bernex #4 | AF13: Bernex #3 | AI13: Kobe #2
B14: 11 | E14: 6 | F14: 2005 | G14: 519680 | H14: 9001889 | I14: 2 | L14: 400V 90kVA | P14: V1.6.2 | Q14: - | AA14: Macoho #2 | AG14: Balzers #2 | AI14: Kobe #1
B15: 12 | E15: 7 | F15: 2008 | G15: 519710 | H15: 9001889 | I15: 3 | P15: V2.0.10 | Q15: - | AC15: CVD Unload | AI15: Kobe #3
B16: 13 | E16: 8 | F16: 2010 | G16: 519725 | H16: 9001889 | I16: 4 | P16: V2.0.15 | Q16: - | AA16: Macoho #3 | AC16: CVD Load | AI16: Balzers #3
B17: 14 | E17: 9 | F17: 2011 | G17: 519727 | H17: 9001889 | I17: 5 | P17: V2.0.15 | Q17: - | AD17: PVD Load(WTA) | AE17: PVD Unload | AF17: PVD Load(Okano) | AG17: Table Cleaner | AH17: Kobe #4 | AI17: Dry Sand
B18: 15 | C18: Loading/Unloading | D18: CVD Loading | E18: 1 | F18: 2013 | G18: SN-1916 | H18: 9001904 | I18: 1 | L18: 220V | N18: PC | O18: - | P18: PC | Q18: - | S18: Cartesian | T18: (Servo)
B19: 16 | D19: CVD Unloading | E19: 1 | F19: 2018 | G19: TTL-1715 | H19: 9000548 | I19: 2 | N19: PC | O19: - | P19: PC | Q19: - | S19: Cartesian | T19: (Servo)
B20: 17 | D20: PVD Loading | E20: 1 | F20: 2013 | G20: SN1915 | H20: 9006017 | I20: 2 | N20: PC | O20: - | P20: PC | Q20: - | S20: Cartesian | T20: (Servo)
B21: 18 | E21: 2 | F21: 2022 | G21: WPVD1M9001 | H21: 9008077 | I21: 1 | R21: Wintech | S21: Mitsubishi | T21: RV-4FRL
B22: 19 | D22: PVD Unloading | E22: 1 | F22: 2018 | G22: TTL-1717 | H22: 9010018 | I22: 2 | N22: PC | O22: - | P22: PC | Q22: - | S22: Cartesian | T22: (Servo)
B23: 20 | C23: Wet Sand | D23: Macoho | E23: 2 | F23: 2012 | G23: 121252 | H23: 9005739 | I23: 2 | N23: Mitsubishi | O23: Q series | P23: Proface | Q23: GP-4000
B24: 21 | E24: 3 | F24: 2019 | G24: 121254 | H24: 9005739 | I24: 3 | N24: Mitsubishi | O24: Q series | P24: Proface | Q24: GP-4000
B25: 22 | E25: 5 | F25: 2024 | G25: 20232077 | H25: 9007707 | I25: 2
B26: 23 | C26: Dry sand | D26: Neo Blast | E26: 1 | F26: 2012 | H26: 6176622 | I26: 1
B27: 24 | E27: 2 | F27: 2024 | G27: NEO-HI-BAS/400 | H27: 6261584 | I27: 1 | L27: 380V
B28: 25 | C28: Table Cleaner | E28: 1 | F28: 2019 | H28: - | I28: - | L28: 220V
H83: 9003763

Sheet 코팅2
B2: Coating2 Machine List
B3: NO | C3: Name | D3: Model | E3: No. | F3: Year | G3: Serial No. | H3: Gal Item No. | I3: No.2 | J3: WCN | K3: PPC | L3: Main Supply | M3: Remark1 | N3: PLC | O3: Model | P3: HMI | Q3: Model | R3: Automation | S3: Robot | T3: Model | U3: Controller | V3: Remark2
B4: 1 | C4: PVD F'ce | D4: Kobe AIP-S70 | E4: 1 | F4: 2012 | G4: EB10395 | H4: 9001962 | I4: 6
B5: 2 | E5: 2 | F5: 2012 | G5: EB10394 | H5: 9001962 | I5: 7
B6: 3 | E6: 3 | F6: 2011 | G6: EB10385 | H6: 9001962 | I6: 5
B7: 4 | E7: 4 | F7: 2023 | G7: EB10656 | H7: 9001962 | I7: 8
B8: 5 | E8: 5 | F8: 2023 | G8: EB10671 | H8: 9001962 | I8: 9
B9: 6 | D9: AIP-S40 | E9: 6 | F9: 2011 | G9: EB10369 | H9: 9004409 | I9: 1
B10: 7 | C10: CVD F'ce | D10: Bernex BPX 530L Tandem | E10: 1 | F10: 2011 | G10: 519746 | H10: 9001889 | I10: 6 | L10: 400V 90kVA
B11: 8 | E11: 2 | F11: 2011 | G11: 519745 | H11: 9001889 | I11: 7 | L11: 400V 90kVA
B12: 9 | E12: 3 | F12: 2011 | G12: 519749 | H12: 9001889 | I12: 8 | L12: 400V 90kVA
B13: 10 | E13: 4 | F13: 2011 | G13: 519747 | H13: 9001889 | I13: 9 | L13: 400V 90kVA
B14: 10 | E14: 5 | F14: 2015 | G14: 19602/526124 | H14: 9001889 | L14: 400V 90kVA | X14: Ibche #3 | Z14: Kobe #6 | AA14: Kobe #2 | AB14: Kobe #1
B15: 11 | E15: 6 | F15: 2015 | G15: 526124 | H15: 9001889 | I15: 11 | L15: 400V 110kVA
B16: 12 | E16: 7 | F16: 2018 | G16: 519799 | H16: 9001889 | I16: 13 | L16: 400V 90kVA | AA16: 코팅2
B17: 13 | C17: Loading/Unloading | D17: CVD Loading | E17: 1 | F17: 2012 | G17: 16678 | H17: 9006018 | I17: 1 | R17: Okano | S17: Cartesian | T17: Cartesian | AD17: Bernex #4 | AE17: Bernex #3
B18: 14 | D18: CVD Unloading | E18: 1 | F18: 2017 | G18: - | H18: 9000548 | I18: 1 | R18: Bitech | S18: Cartesian | T18: Cartesian | AB18: Bernex #6 | AC18: Bernex #2 | AD18: Bernex #1 | AE18: Bernex #7
B19: 15 | D19: PVD Loading | E19: 1 | F19: 2012 | G19: 1743 | H19: 9006017 | I19: 1 | R19: Okano | S19: Cartesian | T19: Cartesian
B20: 16 | D20: PVD Unloading | E20: 1 | F20: 2018 | G20: - | H20: 9010018 | I20: 2 | R20: Bitech | S20: Cartesian | T20: Cartesian | AB20: Macoho #1 | AC20: Macoho #3 | AE20: CVD Loading
B21: 17 | E21: 2 | F21: 2022 | G21: WPVD1M9002 | H21: 9008076 | I21: 1 | L21: 220V | R21: Wintech | S21: Mitsubishi | T21: RV-4FRL | AA21: GRAF | AE21: CVD Unload
B22: 18 | C22: Sand | D22: Macoho | E22: 1 | F22: 2012 | G22: 20121253 | H22: 9005739 | I22: 4 | AB22: Macoho #2 | AD22: PVD Unload
B23: 19 | E23: 2 | F23: 2012 | G23: 20121255 | H23: 9005739 | I23: 5 | AA23: Ultra Clean | AD23: PVD Unload | AE23: PVD Loading
B24: 20 | E24: 3 | F24: 2020 | G24: 20191817 | H24: 9007707 | I24: 1 | AA24: Ibche #1
B25: 21 | C25: GRAF | D25: - | E25: 1 | F25: 2003 | G25: 2432 | H25: 6176686 | I25: 1 | L25: 400V 14kW | AA25: Ibche #2 | AB25: HiPIMS | AC25: Kobe #5 | AD25: Kobe #4 | AE25: Kobe #3
B26: 22 | C26: HiPIMS | D26: Cemecon | E26: 1 | F26: 2019 | G26: 11384 | H26: 9007660 | I26: 1 | N26: BECKHOFF | O26: EK1100 | P26: SEMECON | AA26: Ibche #3 | AC26: Kobe #6 | AD26: Kobe #2 | AE26: Kobe #1
B27: 23 | C27: Diamond | E27: 1 | F27: 2019 | G27: 11388 | H27: 9007661 | I27: 1
H83: 9003763

Sheet 가공
B2: Tools Machine List
B3: NO | C3: Name | D3: Model | E3: No. | F3: Year | G3: Serial No. | H3: Gal Item No. | I3: No.2 | J3: WCN | K3: PPC | L3: Main Supply | M3: Remark1 | N3: PLC | O3: Model | P3: HMI | Q3: Model | R3: Automation | S3: Robot | T3: Model | U3: Controller | V3: Remark2 | W3: Fire Ext.
B4: 1 | C4: Rollomatic | D4: 628XS | E4: 1 | F4: 2012 | G4: 7797 | H4: 9005136 | I4: 20 | L4: 220V | R4: Rollomatic | S4: Cartesian | W4: K&B
B5: 2 | E5: 2 | F5: 2012 | G5: 7666 | H5: 9005136 | I5: 17 | L5: 220V | R5: Rollomatic | S5: Cartesian | W5: K&B
B6: 3 | E6: 3 | F6: 2012 | G6: 7361 | H6: 9005136 | I6: 12 | L6: 220V | R6: Rollomatic | S6: Cartesian | W6: K&B
B7: 4 | E7: 4 | F7: 2012 | G7: 7362 | H7: 9005136 | I7: 13 | L7: 220V | R7: Rollomatic | S7: Cartesian | W7: K&B
B8: 5 | E8: 5 | F8: 2012 | G8: 7136 | H8: 9005136 | I8: 4 | L8: 220V | R8: Rollomatic | S8: Cartesian | W8: K&B
B9: 6 | E9: 6 | F9: 2012 | G9: 7356 | H9: 9005136 | I9: 7 | L9: 220V | R9: Rollomatic | S9: Cartesian | W9: K&B
B10: 7 | E10: 7 | F10: 2012 | G10: 7355 | H10: 9005136 | I10: 6 | L10: 220V | R10: Rollomatic | S10: Cartesian | W10: K&B
B11: 8 | E11: 11 | F11: 2011 | G11: 7660 | H11: 9005136 | I11: 11 | L11: 220V | R11: Rollomatic | S11: Cartesian | W11: K&B
B12: 9 | E12: 12 | F12: 2011 | G12: 7661 | H12: 9005136 | I12: 19 | L12: 220V | R12: Rollomatic | S12: Cartesian | W12: K&B
B13: 10 | E13: 13 | F13: 2011 | G13: 7663 | H13: 9005136 | I13: 26 | L13: 220V | R13: Rollomatic | S13: Cartesian | W13: K&B
B14: 11 | E14: 14 | F14: 2011 | G14: 7664 | H14: 9005136 | I14: 46 | L14: 220V | R14: Rollomatic | S14: Cartesian | W14: K&B
B15: 12 | E15: 15 | F15: 2012 | G15: 7904 | H15: 9005136 | I15: 18 | L15: 220V | R15: Rollomatic | S15: Cartesian | W15: K&B
B16: 13 | E16: 16 | F16: 2011 | G16: 7191 | H16: 9005136 | I16: 5 | L16: 220V | R16: Rollomatic | S16: Cartesian | W16: K&B
... B23: 20 | E23: 26 | F23: 2011 | G23: 7359 | H23: 9005136 | I23: 10 | L23: 220V | R23: Rollomatic | S23: Cartesian | W23: K&B
B24: 21 | E24: 27 | F24: 2011 | G24: 7360 | H24: 9005136 | I24: 48 | L24: 220V | R24: Rollomatic | S24: Cartesian | W24: K&B | AA24: 가공
B25: 22 | E25: 31 | F25: 2010 | G25: 7016 | H25: 9005136 | I25: 1 | L25: 220V | R25: Rollomatic | S25: Cartesian | W25: K&B | AA25: 628XS#1 | AB25: 628XS#2 | AC25: 628XS#3 | AD25: 628XS#4 | AE25: 628XS#5 | AF25: 628XS#6 | AG25: 628XS#7 | AH25: 629XS#8
B26: 23 | E26: 32 | F26: 2010 | G26: 7017 | H26: 9005136 | I26: 2 | L26: 220V | N26: BECKHOFF | O26: EK1100 | P26: SEMECON | R26: Rollomatic | S26: Cartesian | W26: K&B | AA26: 628XS#11 | AB26: 628XS#12 | AC26: 628XS#13 | AD26: 628XS#14 | AE26: 628XS#15 | AF26: 628XS#16 | AG26: 628XS#17 | AH26: 629XS#18
B27: 24 | E27: 41 | F27: 2012 | G27: 7819 | H27: 9005136 | I27: 21 | L27: 220V | R27: Rollomatic | S27: Cartesian | W27: K&B
B28: 25 | E28: 42 | F28: 2012 | G28: 7820 | H28: 9005136 | I28: 22 | L28: 220V | R28: Rollomatic | S28: Cartesian | W28: K&B | AA28: 628XS#21 | AB28: 628XS#22 | AC28: 628XS#23 | AD28: 628XS#24 | AE28: 628XS#25 | AF28: 628XS#26 | AG28: 628XS#27 | AH28: 629XS#28
B29: 26 | E29: 43 | F29: 2012 | G29: 7855 | H29: 9005136 | I29: 23 | L29: 220V | R29: Rollomatic | S29: Cartesian | W29: K&B | AA29: 628XS#31 | AB29: 628XS#32 | AC29: 620XS#33 | AD29: 620XS#34 | AE29: 620XS#35 | AF29: 620XS#36 | AG29: 620XS#37 | AH29: 629XS#38
B30: 27 | E30: 51 | F30: 2012 | G30: 7875 | H30: 9005136 | I30: 24 | L30: 220V | R30: Rollomatic | S30: Cartesian | W30: K&B
B31: 28 | E31: 52 | F31: 2012 | G31: 7877 | H31: 9005136 | I31: 25 | L31: 220V | R31: Rollomatic | S31: Cartesian | W31: K&B | AA31: 628XS#41 | AB31: 628XS#42 | AC31: 628XS#43 | AD31: 620XS#44 | AE31: 620XS#45 | AF31: 629XS#46 | AG31: 629XS#47
B32: 29 | D32: 620XS | E32: 33 | F32: 2008 | G32: 6639 | H32: 9002055 | I32: 10 | L32: 220V | R32: Rollomatic | S32: Cartesian | W32: K&B | AA32: 628XS#51 | AB32: 628XS#52 | AC32: 620XS#53 | AD32: 620XS#54 | AE32: 620XS#55 | AF32: 629XS#56 | AI32: Profile Proj
B33: 30 | E33: 34 | F33: 2008 | G33: 6638 | H33: 9002055 | I33: 9 | L33: 220V | R33: Rollomatic | S33: Cartesian | W33: K&B | AI33: Zoller
B34: 31 | E34: 35 | F34: 2008 | G34: 6621 | H34: 9002055 | I34: 8 | L34: 220V | R34: Rollomatic | S34: Cartesian | W34: K&B | AA34: ANCA#1 | AB34: ANCA#2 | AC34: ANCA#3 | AD34: ANCA#4 | AE34: ANCA#5 | AF34: ANCA#6 | AI34: Haimer
B35: 32 | E35: 36 | F35: 2008 | G35: 6620 | H35: 9002055 | I35: 5 | L35: 220V | R35: Rollomatic | S35: Cartesian | W35: K&B | AA35: ANCA#11 | AB35: ANCA#12 | AC35: ANCA#13 | AD35: ANCA#14 | AE35: ANCA#15 | AF35: ANCA#16 | AI35: Starret
B36: 33 | E36: 37 | F36: 2007 | G36: 5862 | H36: 9002055 | I36: 4 | L36: 220V | R36: Rollomatic | S36: Cartesian | W36: K&B | AI36: OTEC
B37: 34 | E37: 44 | F37: 2003 | G37: 3986 | H37: 9002055 | I37: 2 | L37: 220V | R37: Rollomatic | S37: Cartesian | W37: K&B | AD37: RS700 | AE37: GCX #1 | AF37: MP1200 | AI37: Cooper
B38: 35 | E38: 45 | F38: 2001 | G38: 32 | H38: 9002055 | I38: 1 | L38: 220V | R38: Rollomatic | S38: Cartesian | W38: K&B | AC38: ANCA TX7 | AE38: ANCA TX7 | AF38: GCX #2
B39: 36 | E39: 53 | F39: 2008 | G39: 6619 | H39: 9002055 | I39: 7 | L39: 220V | R39: Rollomatic | S39: Cartesian | W39: K&B | AI39: Kanehira
B40: 37 | E40: 54 | F40: 2008 | G40: 6580 | H40: 9002055 | I40: 6 | L40: 220V | R40: Rollomatic | S40: Cartesian | W40: K&B | AA40: NP5#1 | AB40: NP5#2 | AC40: Centerless#1 | AD40: Centerless#2 | AI40: Wasino
B41: 38 | E41: 55 | F41: 2003 | G41: 3985 | H41: 9002055 | I41: 3 | L41: 220V | R41: Rollomatic | S41: Cartesian | W41: K&B | AA41: NP30#1 | AB41: NP30#2 | AC41: NP50 | AD41: Chamfer | AE41: HMT Cutting | AF41: Rollomatic V2 | AG41: DURR | AI41: Cleveland
B42: 39 | D42: 629XW | E42: 8 | F42: 2017 | G42: 805721 | H42: 9000374 | I42: 1 | L42: 380V | R42: Rollomatic | S42: Cartesian | W42: K&B | AI42: Ultrasonic
B43: 40 | E43: 18 | F43: 2017 | G43: 805722 | H43: 9000374 | I43: 2 | L43: 380V | R43: Rollomatic | S43: Cartesian | W43: K&B | AC43: Laser Mark | AD43: Laser Mark | AF43: Aero Lap | AG43: Studer S20 | AH43: Daewoo Turn | AI43: Daewoo Turn
B44: 41 | E44: 28 | F44: 2018 | G44: 805820 | H44: 9000374 | I44: 3 | L44: 380V | R44: Rollomatic | S44: Cartesian | W44: K&B
B45: 42 | E45: 38 | F45: 2018 | G45: 805822 | H45: 9000374 | I45: 4 | L45: 380V | R45: Rollomatic | S45: Cartesian | W45: K&B
B46: 43 | E46: 46 | F46: 2018 | G46: 806984 | H46: 9000374 | I46: 5 | L46: 380V | R46: Rollomatic | S46: Cartesian | W46: K&B
B47: 44 | E47: 47 | F47: 2018 | G47: 806985 | H47: 9000374 | I47: 6 | L47: 380V | R47: Rollomatic | S47: Cartesian | W47: K&B
...

Sheet MC
B2: M/C Machine List
B3: NO | C3: Name | D3: Model | E3: No. | F3: Year | G3: Serial No. | H3: Gal Item No. | I3: No.2 | J3: WCN | K3: PPC | L3: Main Supply | M3: Remark1 | N3: PLC | O3: Model | P3: HMI | Q3: Model | R3: Automation | S3: Robot | T3: Model | U3: Controller | V3: Remark2
B4: 1 | C4: Hermle Milling | D4: C30U | E4: 3 | F4: 2005 | G4: 17343 | H4: 9005211 | I4: 3 | R4: Shafir | S4: Cylindrical | U4: Siemens
B5: 2 | E5: 4 | F5: 2005 | G5: 17326 | H5: 9005211 | I5: 4 | R5: Shafir | S5: Cylindrical | U5: Siemens
B6: 3 | E6: 5 | F6: 2006 | G6: 17561 | H6: 9005211 | I6: 5 | R6: Shafir | S6: Cylindrical | U6: Siemens
B7: 4 | E7: 6 | F7: 2005 | G7: 17324 | H7: 9005211 | I7: 6 | R7: Shafir | S7: Cylindrical | U7: Siemens
B8: 5 | E8: 7 | F8: 2005 | G8: 17319 | H8: 9005211 | I8: 7 | R8: Shafir | S8: Cylindrical | U8: Siemens
B9: 6 | E9: 8 | F9: 2005 | G9: 17342 | H9: 9005211 | I9: 8 | R9: Shafir | S9: Cylindrical | U9: Siemens
B10: 7 | E10: 9 | F10: 2006 | G10: 17552 | H10: 9005211 | I10: 9 | R10: Shafir | S10: Cylindrical | U10: Siemens
B11: 8 | E11: 10 | F11: 2006 | G11: 17553 | H11: 9005211 | I11: 10 | R11: Shafir | S11: Cylindrical | U11: Siemens
B12: 9 | E12: 11 | F12: 2008 | G12: 19241 | H12: 9005211 | I12: 11
B13: 10 | E13: 12 | F13: 2008 | G13: 19242 | H13: 9005211 | I13: 12
B14: 11 | E14: 14 | F14: 2010 | G14: 20150 | H14: 9005211 | I14: 14 | R14: Shafir | S14: Manipulator | V14: Beckhoff CX5020
B15: 12 | E15: 15 | F15: 2011 | G15: 20586 | H15: 9005211 | I15: 15 | R15: Shafir | S15: Manipulator | V15: Beckhoff CX5020
B16: 13 | E16: 16 | F16: 2011 | G16: 20587 | H16: 9005211 | I16: 21 | R16: Shafir | S16: Manipulator | V16: Beckhoff CX5020
B17: 14 | E17: 17 | F17: 2011 | G17: 20588 | H17: 9005211 | I17: 22 | R17: Shafir | S17: Manipulator | V17: Beckhoff CX5020
B18: 15 | E18: 18 | F18: 2011 | G18: 20589 | H18: 9005211 | I18: 23 | R18: Shafir | S18: Manipulator | V18: Beckhoff CX5020
B19: 16 | E19: 19 | F19: 2013 | G19: 22204 | H19: 9005211 | I19: 26 | R19: Shafir | S19: Yaskawa | T19: HP20F | U19: MP2300 | V19: Beckhoff CX5010
B20: 17 | E20: 20 | F20: 2013 | G20: 22216 | H20: 9005211 | I20: 27 | R20: Shafir | S20: Yaskawa | T20: HP20F | U20: MP2300 | V20: Beckhoff CX5010
B21: 18 | E21: 21 | F21: 2013 | G21: 22189 | H21: 9005211 | I21: 28 | R21: Shafir | S21: Yaskawa | T21: HP20F | U21: MP2300 | V21: Beckhoff CX5010
B22: 19 | D22: C40U | E22: 13 | F22: 2010 | G22: 20173 | H22: 9004930 | I22: 13
B23: 20 | D23: C32U | E23: 25 | F23: 2018 | G23: 25880 | H23: 9006876 | I23: 2 | AA23: M/C
B24: 21 | E24: 26 | F24: 2018 | G24: 25881 | H24: 9006876 | I24: 3 | AB24: C42U#22 | AC24: C42U#23 | AD24: C30U#12 | AE24: C30U#11
B25: 22 | D25: C42U | E25: 22 | F25: 2013 | G25: 22320 | H25: 9005955 | I25: 1 | AB25: C42U#24 | AC25: C40U#13 | AD25: C32U#25 | AE25: C32U#26 | AF25: Zoller
B26: 23 | E26: 23 | F26: 2015 | G26: 23799 | H26: 9005955 | I26: 2 | AF26: Zoller
B27: 24 | E27: 24 | F27: 2015 | G27: 23800 | H27: 9005955 | I27: 3 | AA27: PUMA#2 | AB27: C30U#8 | AC27: C30U#4 | AD27: C30U#17 | AE27: C30U#16 | AF27: Gom
B28: 25 | C28: Mazak Turning | D28: Integrex 200 | E28: 1 | F28: 2005 | G28: 180027 | H28: 9003690 | I28: 1 | AA28: VT900ML | AB28: C30U#5 | AC28: C30U#10 | AD28: C30U#7 | AE28: C30U#9 | AF28: Lasit
B29: 26 | D29: HQR | E29: 1 | F29: 2012 | G29: 233299 | H29: 9006230 | I29: 1
B30: 27 | E30: 2 | F30: 2012 | G30: 233300 | H30: 9006230 | I30: 2 | AB30: C30U#18 | AC30: C30U#15 | AD30: C30U#14 | AE30: C30U#19
B31: 28 | D31: W-300Y | E31: 1 | F31: 2023 | G31: B83344860 | H31: 9008183 | I31: 1 | AA31: e-500H | AB31: C30U#6 | AC31: C30U#3 | AD31: C30U#21 | AE31: C30U#20
B32: 29 | D32: i-200 | E32: 1 | F32: 2024 | G32: 344748 | H32: 9008185 | I32: 1
B33: 30 | D33: i-200 | E33: 2 | F33: 2024 | G33: 344749 | H33: 9008185 | I33: 2 | AB33: i-200 | AC33: i-200 | AD33: W-300Y
B34: 31 | D34: e-500 | E34: 1 | F34: 2024 | G34: 344750 | H34: 9008184 | I34: 1 | AB34: INT200 | AC34: HQR#2 | AD34: HQR#1
B35: 32 | C35: Puma | D35: 300MB | E35: 2 | F35: 2005 | G35: P30M1732 | H35: 9003335 | I35: 1
B36: 33 | D36: VT900M | E36: 1 | F36: 2020 | G36: - | H36: 9007901 | I36: 1 | AB36: Gun drill #1 | AC36: TAIYO Koki | AD36: Youil G/R | AE36: Rotary G/R | AF36: CVG9
B37: 34 | C37: Gun drill | D37: SMGK-600 CNC | E37: 1 | F37: 1998 | G37: 15138 | H37: 9005781 | I37: 1
B38: 35 | C38: DMG MORI | D38: NVGH-3T | E38: 1 | F38: 2021 | G38: 4766 | H38: 9000429 | I38: 1 | R38: Cellro | S38: Fanuc | T38: M-20iD | AA38: M/C_범용실 | AD38: M/C_삼원
B39: 36 | D39: CVG-9 | E39: 1 | F39: 2024 | G39: 5355 | H39: 9008313 | I39: 1 | AA39: Bridgeport #1 | AB39: Band Saw | AC39: Studer S40 | AD39: Cooper | AE39: Cooper | AF39: Korea Sonic
B40: 37 | C40: Youil grinder | D40: YGS-96A | E40: 1 | F40: 2024 | G40: 96240213 | H40: 9005527 | I40: 2 | AA40: Bridgeport #2 | AC40: OD Grinder
B41: 38 | C41: Rotary Grinder | D41: WASINO SS-501 | E41: 1 | F41: 1987 | G41: 195-0-0179 | H41: 9003404 | I41: 1 | AA41: Hwacheon
...

Sheet 드릴
B2: Drill Machine List
B3: NO | C3: Name | D3: Model | E3: No. | F3: Year | G3: Serial No. | H3: Gal Item No. | I3: No.2 | J3: WCN | K3: PPC | L3: Main Supply | M3: Remark1 | N3: PLC | O3: Model | P3: HMI | Q3: Model | R3: Automation | S3: Robot | T3: Model | U3: Controller | V3: Remark2
B4: 1 | C4: Hermle Milling | D4: C30U | E4: 1 | F4: 2011 | G4: 20577 | H4: 9005211 | I4: 16 | L4: 400V 41kVA | R4: Shafir | S4: Cylindrical | V4: Beckhoff CX5020
B5: 2 | E5: 2 | F5: 2011 | G5: 20578 | H5: 9005211 | I5: 17 | L5: 400V 41kVA | R5: Shafir | S5: Cylindrical | V5: Beckhoff CX5020 | AA5: 드릴
B6: 3 | E6: 3 | F6: 2012 | G6: 21515 | H6: 9005211 | I6: 18 | L6: 400V 41kVA | R6: Shafir | S6: Cylindrical | V6: Beckhoff CX5020 | AA6: TWIST1~6
B7: 4 | E7: 4 | F7: 2012 | G7: 21516 | H7: 9005211 | I7: 19 | L7: 400V 41kVA | R7: Raon | S7: Fanuc | T7: M-20iD | V7: 2024. 11개조 | AB7: OTEC
B8: 5 | E8: 5 | F8: 2012 | G8: 21514 | H8: 9005211 | I8: 20 | L8: 400V 41kVA | R8: Raon | S8: Fanuc | T8: M-20iD | V8: 2024. 11개조 | AA8: Studer S33 | AB8: Laser (Hitech) | AD8: DMG MORI #1 | AE8: sugino#1 | AF8: Gun drill#2
B9: 6 | E9: 6 | F9: 2013 | G9: 22365 | H9: 9005211 | I9: 24 | L9: 400V 41kVA | R9: Shafir | S9: Yaskawa | T9: HP20F | U9: MP2300 | V9: Beckhoff CX5010 | AA9: Studer S36 | AB9: Laser #4 | AE9: sugino#2 | AF9: Gun drill#3
B10: 7 | E10: 7 | F10: 2013 | G10: 22369 | H10: 9005211 | I10: 25 | L10: 400V 41kVA | R10: Shafir | S10: Yaskawa | T10: HP20F | U10: MP2300 | V10: Beckhoff CX5010 | AA10: Toyoda | AB10: makino#5 | AD10: DMG MORI #2 | AF10: makino#9
B11: 8 | D11: C42U | E11: 8 | F11: 2015 | G11: 23631 | H11: 9005955 | I11: 4 | L11: 400V 45kVA
B12: 9 | E12: 9 | F12: 2018 | G12: 25878 | H12: 9005955 | I12: 6 | L12: 400V 37kVA | AA12: makino#2 | AB12: makino#4 | AD12: makino#7 | AE12: C32U#12 | AF12: makino#11
B13: 10 | D13: C32U | E13: 10 | F13: 2018 | G13: 25879 | H13: 9006876 | I13: 1 | L13: 400V 37kVA | R13: Cellro | S13: Fanuc | T13: M-20iA | AA13: makino#1 | AB13: makino#3 | AD13: makino#6 | AE13: C32U#11 | AF13: makino#10
B14: 11 | E14: 11 | F14: 2020 | G14: 27851 | H14: 9006876 | I14: 4 | L14: 400V 46KVA | R14: Cellro | S14: Fanuc | T14: M-20iA
B15: 12 | E15: 12 | F15: 2020 | G15: 27968 | H15: 9006876 | I15: 9 | L15: 400V 46KVA | R15: Cellro | S15: Fanuc | T15: M-20iA | AA15: C32U#10 | AB15: C42U#8 | AD15: C30U#7 | AE15: C30U#5 | AF15: C30U#3
B16: 13 | C16: Makino Milling | D16: α51-5XU (7-axis) | E16: 1 | F16: 2010 | G16: 1754 | H16: 9003606 | I16: 1 | L16: 220V | R16: Erowa | S16: Cylindrical | T16: - | U16: ECU | AA16: C30U#1 | AB16: C42U#9 | AD16: C30U#6 | AE16: C30U#4 | AF16: C30U#2
B17: 14 | E17: 2 | F17: 2011 | G17: 2362 | H17: 9003606 | I17: 2 | L17: 220V | R17: Erowa | S17: Cylindrical | T17: - | U17: ECU | AE17: Blast - M/C범용실
B18: 15 | E18: 3 | F18: 2011 | G18: 2350 | H18: 9003606 | I18: 3 | L18: 220V | R18: Erowa | S18: Cylindrical | T18: - | U18: ECU
B19: 16 | E19: 4 | F19: 2011 | G19: 2349 | H19: 9003606 | I19: 4 | L19: 220V | R19: Erowa | S19: Cylindrical | T19: - | U19: ECU
B20: 17 | E20: 5 | F20: 2011 | G20: 2351 | H20: 9003606 | I20: 5 | L20: 220V | R20: Erowa | S20: Cylindrical | T20: - | U20: ECU
B21: 18 | E21: 6 | F21: 2010 | G21: 1755 | H21: 9003606 | I21: 6 | L21: 220V | R21: Erowa | S21: Cylindrical | T21: - | U21: ECU
B22: 19 | E22: 7 | F22: 2011 | G22: 1753 | H22: 9003606 | I22: 7 | L22: 220V | R22: Erowa | S22: Cylindrical | T22: - | U22: ECU
B23: 20 | E23: 9 | F23: 2010 | G23: 2367 | H23: 9003623 | I23: 9 | L23: 220V | R23: Erowa | S23: Cylindrical | T23: - | U23: ECU
B24: 21 | E24: 10 | F24: 2012 | G24: 2955 | H24: 9003623 | I24: 10 | L24: 220V | M24: 미가동 | R24: Erowa | S24: Cylindrical | T24: - | U24: ECU
B25: 22 | E25: 11 | F25: 2012 | G25: 2366 | H25: 9003623 | I25: 11 | L25: 220V | R25: Erowa | S25: Cylindrical | T25: - | U25: ECU
B26: 23 | C26: Gun drill Deep-Drilling | D26: Gun drill | E26: 2 | F26: 2003 | G26: 15069 | H26: 9005520 | I26: 1 | L26: 220V
B27: 24 | E27: 3 | F27: 2010 | G27: 15164 | H27: 9005520 | I27: 3 | L27: 220V
B28: 25 | D28: Sugino | E28: 4 | F28: 2013 | G28: 132018 | H28: 9005744 | I28: 1 | L28: 220V | R28: Cellro | S28: Fanuc | T28: Arcmate 120iC
B29: 26 | E29: 5 | F29: 2015 | G29: 156025 | H29: 9005744 | I29: 2 | L29: 220V | R29: Cellro | S29: Fanuc | T29: Arcmate 120iC
B30: 27 | C30: Twist | D30: - | E30: 1 | F30: 2002 | G30: - | H30: 9002754 | I30: 1 | L30: 220V 1P
B31: 28 | E31: 2 | F31: 2003 | G31: - | H31: 9002754 | I31: 2 | L31: 220V 1P
B32: 29 | E32: 3 | F32: 2006 | G32: - | H32: 9002754 | I32: 3 | L32: 220V 1P
B33: 30 | D33: TWM-104 | E33: 4 | F33: 2012 | G33: SR1206-A-350 | H33: 9002754 | I33: 4 | L33: 220V 1P
B34: 31 | E34: 5 | F34: 2013 | G34: - | H34: 9002754 | I34: 5 | L34: 220V 1P
B35: 32 | D35: TWM-106 | E35: 6 | F35: 2015 | G35: A-380 | H35: 9002754 | I35: 6 | L35: 220V 1P
B36: 33 | C36: OTEC Honing | D36: OTEC | E36: 1 | F36: 2013 | G36: SF130040 | H36: 9006006 | I36: 1 | L36: 400V | R36: Cellro | S36: Fanuc | T36: Arcmate 100iC
B37: 34 | C37: Studer | D37: S36 | E37: 1 | F37: 1998 | G37: 020.0619.90.073 | H37: 9004210 | I37: 1 | L37: 380V
B38: 35 | D38: S33 | E38: 1 | F38: 2006 | G38: 027.0384 | H38: 9003628 | I38: 1 | L38: 400V 29A
B39: 36 | C39: DMG MORI Turning | D39: NZX2000 | E39: 1 | F39: 2021 | G39: NZX23201102 | H39: 9004894 | I39: 1 | L39: 220V 104kVA | R39: Robojob | S39: Fanuc | T39: M-20iA
B40: 37 | D40: NZX2000 | E40: 1 | F40: 2023 | G40: NZX23230603 | H40: 9004894 | I40: 2 | L40: 200V 116KVA
B41: 38 | C41: TOYODA Grinding | D41: GL5Ai-63 | E41: 1 | F41: 2021 | G41: RG-0085 | H41: 9007943 | I41: 1 | L41: 220V 37kVA | R41: Toyoda | S41: Fanuc | T41: CRX-10iA
...

Sheet 세라믹
B2: Ceramic Machine List
B3: NO | C3: Name | D3: Model | E3: No. | F3: Year | G3: Serial No. | H3: Gal Item No. | I3: No.2 | J3: WCN | K3: PPC | L3: Main Supply | M3: Remark1 | N3: PLC | O3: Model | P3: HMI | Q3: Model | R3: Automation | S3: Robot | T3: Model | U3: Controller | V3: Remark2 | W3: Fire Ext.
B4: 1 | C4: Waida Periphery Grinder | D4: AP710A | E4: 1 | F4: 2009 | G4: 124 | H4: 9005443 | I4: 1 | L4: 200V 14kVA | R4: Waida | S4: IAI | T4: IX-NNW7020 | U4: XSEL-QX5-NNW7020-100A-PR-E-EEE-0-3-SP | W4: Kraft&Bauer
B5: 2 | E5: 2 | F5: 2010 | G5: 123 | H5: 9005443 | I5: 2 | R5: Waida | S5: IAI | T5: IX-NNW7020 | U5: XSEL-QX5-NNW7020-100A-PR-E-EEE-0-3-SP
B6: 3 | E6: 3 | F6: 2010 | G6: 121 | H6: 9005443 | I6: 3 | R6: Waida | S6: IAI | T6: IX-NNW7020 | U6: XSEL-QX5-NNW7020-100A-PR-E-EEE-0-3-SP
B7: 4 | E7: 4 | F7: 2010 | G7: 125 | H7: 9005443 | I7: 4 | R7: Waida | S7: IAI | T7: IX-NNW7020 | U7: XSEL-QX5-NNW7020-100A-PR-E-EEE-0-3-SP
B8: 5 | E8: 5 | F8: 2010 | G8: 126 | H8: 9005443 | I8: 5 | R8: Waida | S8: IAI | T8: IX-NNW7020 | U8: XSEL-QX5-NNW7020-100A-PR-E-EEE-0-3-SP
B9: 6 | E9: 6 | F9: 2010 | G9: 127 | H9: 9005443 | I9: 6 | R9: Waida | S9: IAI | T9: IX-NNW7020 | U9: XSEL-QX5-NNW7020-100A-PR-E-EEE-0-3-SP
B10: 7 | E10: 7 | F10: 2010 | G10: 133 | H10: 9005443 | I10: 7 | R10: Waida | S10: IAI | T10: IX-NNW7020 | U10: XSEL-QX5-NNW7020-100A-PR-E-EEE-0-3-SP
B11: 8 | E11: 8 | F11: 2010 | G11: 134 | H11: 9005443 | I11: 8 | R11: Waida | S11: IAI | T11: IX-NNW7020 | U11: XSEL-QX5-NNW7020-100A-PR-E-EEE-0-3-SP
B12: 9 | E12: 9 | F12: 2010 | G12: 135 | H12: 9005443 | I12: 9 | R12: Waida | S12: IAI | T12: IX-NNW7020 | U12: XSEL-QX5-NNW7020-100A-PR-E-EEE-0-3-SP
B13: 10 | E13: 10 | F13: 2010 | G13: 136 | H13: 9005443 | I13: 10 | R13: Waida | S13: IAI | T13: IX-NNW7020 | U13: XSEL-QX5-NNW7020-100A-PR-E-EEE-0-3-SP
B14: 11 | E14: 11 | F14: 2010 | G14: 137 | H14: 9005443 | I14: 11 | R14: Waida | S14: IAI | T14: IX-NNW7020 | U14: XSEL-QX5-NNW7020-100A-PR-E-EEE-0-3-SP
B15: 12 | E15: 12 | F15: 2012 | G15: 165 | H15: 9005443 | I15: 16 | R15: Waida | S15: IAI | T15: IX-NNW7020 | U15: XSEL-QX5-NNW7020-100A-PR-E-EEE-0-3-SP
B16: 13 | D16: APX105 | E16: 1 | F16: 2019 | G16: 179 | H16: 9000428 | I16: 5 | L16: 200V 12kVA | R16: Waida | S16: Yamaha | T16: YK800XGP | U16: SR1-X
B17: 14 | E17: 2 | F17: 2019 | G17: 180 | H17: 9000428 | I17: 6 | R17: Waida | S17: Yamaha | T17: YK800XGP | U17: SR1-X
B18: 15 | E18: 3 | F18: 2020 | G18: 192 | H18: 9000428 | I18: 10 | R18: Waida | S18: Yamaha | T18: YK800XGP | U18: SR1-X
B19: 16 | E19: 4 | F19: 2020 | G19: 194 | H19: 9000428 | I19: 11 | R19: Waida | S19: Yamaha | T19: YK800XGP | U19: SR1-X
B20: 17 | C20: Wendt | D20: WBM200/21 | E20: 1 | F20: 1990 | G20: 854032605X | H20: 9003506 | I20: 2 | L20: 380V
B21: 18 | D21: WBM222RP | E21: 1 | F21: 1995 | G21: 854143803A | H21: 9003511 | I21: 3
B22: 19 | C22: Lasertec50 | D22: DMG SAUER | E22: 1 | F22: 2011 | G22: 12010000147 | H22: 9006072 | I22: 1 | L22: 400V 54kVA | R22: HRT | S22: Universal | T22: UR10e | U22: UR10e
B23: 20 | C23: 원심분리기 | D23: SF-200A | E23: 1 | M23: 2023 폐기 예정
B24: 21 | E24: 2 | M24: 2023 폐기 예정
B25: 22 | E25: 3 | M25: 2023 폐기 예정
B26: 23 | C26: 초음파세척기 | D26: KSU-5ST-40H | E26: 1 | F26: 2024 | G26: 240718 | H26: 9005643 | I26: 2 | R26: * 기존 자동 세척기 폐기
B27: 24 | D27: 수동 | E27: 1 | F27: 1997 | G27: - | H27: - | I27: -
B28: 25 | C28: Wire Alpha-OIB | D28: Fanuc Robocut | E28: 1 | F28: 2003 | G28: 032B0492 | H28: 1154414 | I28: 1 | L28: 220V
B29: 26 | C29: Vaccum brazing | D29: VFS-MH-100 | E29: 1 | F29: 2017 | G29: VFS-MH-100 | H29: 6319547 | I29: 1 | AA29: 세라믹
B30: 27 | C30: EWAG | D30: RS-15 | E30: 1 | F30: 1994 | G30: 159506035 | H30: 9002616 | I30: 1 | L30: 220V | AA30: S/D #1 | AC30: S/D #3 | AE30: B/M #6 | AF30: B/M #7
B31: 28 | E31: 2 | F31: 2006 | G31: 15210264 | H31: 9002616 | I31: 2 | L31: 230V | R31: EWAG | S31: Fanuc | T31: LR Mate 200iD | AE31: B/M #8 | AF31: B/M #5
B32: 29 | C32: Polishing (Honing) | D32: - | E32: 1 | F32: - | H32: - | I32: - | AA32: Screen #1~3 | AE32: B/M #10 | AF32: B/M #9 | AG32: B/M #4
B33: 30 | C33: Tool grinder | D33: C-40 | E33: 1 | F33: 1995 | G33: 102041 | H33: 9005524 | I33: 4 | L33: 220V | AF33: B/M #2 | AG33: B/M #1
B34: 31 | C34: Laser marking | D34: LASIT | E34: 1 | F34: 2007 | G34: E9418 | H34: 9001807 | I34: 1 | L34: 400VAC
B35: 32 | C35: Blanchard 표면연삭 | D35: 11A20 | E35: 1 | F35: 1991 | G35: 15785 | H35: 9003505 | I35: 2 | L35: 110V | AB35: SP80 #1 | AC35: SP80 #2 | AE35: 화천선반 #1 | AF35: Milling M/C
B36: 33 | C36: EWAG | D36: Compact Line | E36: 1 | F36: 2022 | G36: 7188-0265 | H36: 9005001 | I36: 1 | W36: Kraft&Bauer | AA36: Daehwa 60t | AG36: Tool grinder
B37: 34 | C37: Debinding F'ce | D37: - | E37: 1 | F37: 2011 | G37: IVA-173 | H37: 9005935 | I37: 1 | AB37: Hyd #1 | AC37: Hyd #2 | AE37: 선반 #4 | AF37: Band saw | AG37: Wet CIP
B38: 35 | C38: Sinter F'ce | D38: High Vaccum | E38: 2 | F38: 1998 | H38: 9005677 | I38: 11
B39: 36 | D39: H/N | E39: 1 | F39: 2004 | H39: 9005589 | I39: 1 | AB39: Debinding | AC39: FCT SIN#2
B40: 37 | E40: 2 | F40: 2004 | H40: 9005589 | I40: 2 | AB40: H/N#5 | AC40: FCT SIN#3
B41: 38 | E41: 5 | F41: 2005 | H41: 9003672 | I41: 1 | AB41: H/N#2 | AC41: FCT 소결로#2 | AE41: Kobe Sinter
...

Sheet QA
B2: QA Machine List
B3: NO | C3: Name | D3: Model | E3: No. | F3: Year | G3: Serial No. | H3: Gal Item No. | I3: No.2 | J3: WCN | K3: PPC | L3: Main Supply | M3: Remark1 | N3: PLC | O3: Model | P3: HMI | Q3: Model | R3: Automation | S3: Robot | T3: Model | U3: Controller | V3: Remark2 | AB3: 검사실-1
B4: 1 | C4: AVIM | E4: 1 | F4: 2008 | H4: 9004480 | I4: 1 | R4: 성림비전 | S4: Adept | T4: S600 | AB4: AVIM #1
B5: 2 | E5: 2 | F5: 2009 | H5: 9004480 | I5: 2 | R5: 성림비전 | S5: Adept | T5: S800 | AB5: AVIM #2 | AC5: AVIM #3
B6: 3 | E6: 3 | F6: 2011 | H6: 9004480 | I6: 3 | R6: 성림비전 | S6: Adept | T6: S800
B7: 4 | E7: 4 | F7: 2014 | H7: 9006290 | I7: 1 | R7: 성림비전 | S7: Adept | T7: S800 (Dual) | AA7: 검사실-2
B8: 5 | E8: 5 | F8: 2014 | H8: 9006290 | I8: 2 | R8: 성림비전 | S8: Adept | T8: S800 (Dual) | AB8: AVIM #6 | AC8: AVIM #4
B9: 6 | D9: AVIM-23-01 | E9: 6 | F9: 2023 | G9: SR23-09-01 | H9: 9008162 | I9: 1 | L9: 220V 3상 | R9: 성림비전 | S9: Cartesian | AA9: Demagnet | AB9: ADIM | AC9: AVIM #5
B10: 7 | C10: ADIM | D10: HIM-M | E10: 1 | F10: 2024 | G10: WHIM404001 | H10: 9008318 | I10: 2 | R10: 윈텍 | AA10: Laser Mark | AB10: Okano #1 | AC10: Okano #3
B11: 8 | C11: HC/RMS | D11: SM-HC | E11: 1 | F11: 2012 | H11: 9006062 | I11: 1 | R11: 석진산업 | S11: Yamaha | T11: TH850A | AA11: Inkjet | AB11: Okano #2 | AC11: Okano #4
C16: Vision Inspection/Loading machine List
C17: Department | D17: Model | E17: Year | F17: Serial No. | G17: Gal Item No. | H17: Vendor | R17: 전기도면 | S17: 하드백업 | T17: 배선도
C18: Coating 1 | D18: PVD Loading | E18: 2013 | F18: SN1915 | G18: 9006017 | H18: Okano | R18: O
D19: PVD Unloading | E19: 2018 | F19: TTL-1717 | G19: 9010018 | H19: 바이텍 | R19: X
D20: PVD Unloading | E20: 2022 | F20: WPVD1M9002 | G20: 9008076 | H20: 윈텍
D21: CVD Loading | E21: 2013 | F21: SN-1916 | G21: 9001904 | H21: Okano
D22: CVD Unloading | E22: 2018 | F22: TTL-1715 | G22: 9000548 | H22: 바이텍
C23: Coating 2 | D23: PVD Loading | E23: 2022 | F23: WPVD1M9001 | G23: 9008077 | H23: 윈텍
D24: PVD Loading | E24: 2012 | F24: 1743 | G24: 9006017 | H24: Okano
D25: PVD Unloading | E25: 2018 | F25: - | G25: 9010018 | H25: 바이텍
D26: CVD Loading | E26: 2012 | F26: 16678 | G26: 9006018 | H26: Okano
D27: CVD Unloading | E27: 2017 | F27: - | G27: 9000548 | H27: 바이텍
C28: QA | D28: AVIM | E28: 2008 | G28: 9004480 | H28: 성림비전
E29: 2009 | G29: 9004480 | H29: 성림비전
E30: 2011 | G30: 9004480 | H30: 성림비전
E31: 2014 | G31: 9006290 | H31: 성림비전
E32: 2014 | G32: 9006290 | H32: 성림비전
E33: 2023 | F33: SR23-09-01 | G33: 9004480 | H33: 성림비전
H83: 9003763

Sheet 성능
B2: Tech-Center Machine List
B3: NO | C3: Name | D3: Model | E3: No. | F3: Year | G3: Serial No. | H3: Gal Item No. | I3: No.2 | J3: WCN | K3: PPC | L3: Main Supply | M3: Remark1 | N3: PLC | O3: Model | P3: HMI | Q3: Model | S3: 성능시험팀
B4: 1 | C4: Mori-Seiki Vertical | D4: NVD4000DCG | E4: 1 | F4: 2008 | G4: NV401HF1414 | H4: 9004837 | I4: 1 | S4: VRX630 | U4: PUMA480
B5: 2 | D5: MV-653 | E5: 1 | F5: 2008 | G5: MV653HE0489 | H5: 9002887 | I5: 4 | S5: NVD4000 | U5: PUMA4100 | W5: G550 | X5: VM750
B6: 3 | C6: Mazak | D6: Inter E-500H | E6: 1 | F6: 2010 | G6: 221864 | H6: 9003627 | I6: 1 | S6: Yamage | U6: PUMA300
B7: 4 | D7: VRX630-5X2 | E7: 1 | F7: 2010 | G7: 550223969 | H7: 9002909 | I7: 1 | S7: VM650 | U7: Puma2100
B8: 5 | D8: Integrex i-350H | E8: 1 | F8: 2023 | G8: 344751 | H8: 9009986 | I8: 1 | S8: MV653 | W8: E-500H | X8: i-350H
B9: 6 | C9: Puma Turning | D9: PUMA480 | E9: 1 | F9: 2008 | G9: PM4800158 | H9: 9004840 | I9: 1 | T9: STAR
B10: 7 | D10: PUMA4100A | E10: 1 | F10: 2019 | G10: ML0272-000055 | H10: 9007627 | I10: 1
B11: 8 | D11: PUMA300LC | E11: 1 | F11: 2014 | G11: ML0065-003900 | H11: 9007078 | I11: 1
B12: 9 | D12: PUMA2100L | E12: 1 | F12: 2022 | G12: ML0095-000346 | H12: 9008103 | I12: 1
B13: 10 | C13: Doosan Turning | D13: VM750 | E13: 1 | F13: 2019 | G13: MV0026-001425 | H13: 9007634 | I13: 1
B14: 11 | D14: VM650 | E14: 1 | F14: 2002 | G14: AM650032 | H14: 6178940 | I14: 1
B15: 12 | C15: STAR | D15: SR-32J2 II-A | E15: 1 | F15: 2017 | G15: 0129(lot.017) | H15: 9000706 | I15: 1
B16: 13 | C16: Yamage Milling | D16: YFC-V500 | E16: 1 | F16: 1999 | G16: 5074 | H16: 6177951 | I16: 1
B17: 14 | C17: GROB | D17: G550 | E17: 1 | F17: 2023 | G17: G552-10255 | H17: 9008197 | I17: 1
H83: 9003763

Sheet Tech-Office
B2: Tech-Office Machine List
B3: NO | C3: Name | D3: Model | E3: No. | F3: Year | G3: Serial No. | H3: Gal Item No. | I3: No.2 | J3: WCN | K3: PPC | L3: Main Supply | M3: Remark1
B4: 1 | C4: 3D Print | D4: M2 CUSING | E4: 1 | F4: 2018 | G4: 6618G03063 | I4: 1
B5: 2 | D5: M2 SERIES-5 DL-400 | E5: 1 | F5: 2023 | G5: GEADDL-M2-900157 | H5: 9008165 | I5: 1 | S5: Tech (Drill)
